<?xml version="1.0" ?>

<sdf version='1.6'>

  <model name='custom_drone_with_manipulator'>

    <link name='custom_drone__fuselage'>
      <pose frame=''>0 0 0 0 -0 0</pose>
      <inertial>
        <pose frame=''>-0.000773 0 0.005713 0 -0 0</pose>
        <mass>2.07912</mass>
        <inertia>
          <ixx>0.0233947</ixx>
          <ixy>1.22034e-21</ixy>
          <ixz>0.000232102</ixz>
          <iyy>0.0234355</iyy>
          <iyz>5.41873e-23</iyz>
          <izz>0.0400506</izz>
        </inertia>
      </inertial>
      <collision name='custom_drone__fuselage_collision_collision'>
        <pose frame=''>0 0 0.175 0 -0 0</pose>
        <geometry>
          <box>
            <size>0.459619 0.459619 0.25</size>
          </box>
        </geometry>
      </collision>
      <collision name='custom_drone__fuselage_fixed_joint_lump__link1_collision_1'>
        <pose frame=''>-0.02 0 0.15 3.14159 -0.041593 3.14159</pose>
        <geometry>
          <mesh>
            <scale>0.001 0.001 0.001</scale>
            <uri>model://custom_drone_with_manipulator/meshes/chain_link1.stl</uri>
          </mesh>
        </geometry>
        <surface>
          <contact>
            <ode>
              <kp>1e+06</kp>
              <kd>100</kd>
              <max_vel>1</max_vel>
              <min_depth>0.001</min_depth>
            </ode>
          </contact>
          <friction>
            <ode>
              <mu>30</mu>
              <mu2>30</mu2>
            </ode>
          </friction>
        </surface>
      </collision>
      <visual name='custom_drone__fuselage_visual_visual'>
        <pose frame=''>0 0 0.2 0 -0 0</pose>
        <geometry>
          <mesh>
            <scale>1 1 1</scale>
            <uri>model://custom_drone_with_manipulator/meshes/Matrice_100.dae</uri>
          </mesh>
        </geometry>
      </visual>
      <visual name='custom_drone__fuselage_fixed_joint_lump__link1_visual_1'>
        <pose frame=''>-0.02 0 0.15 3.14159 -0.041593 3.14159</pose>
        <geometry>
          <mesh>
            <scale>0.001 0.001 0.001</scale>
            <uri>model://custom_drone_with_manipulator/meshes/chain_link1.stl</uri>
          </mesh>
        </geometry>
        <material>
          <script>
            <name>Gazebo/DarkGrey</name>
            <uri>file://media/materials/scripts/gazebo.material</uri>
          </script>
        </material>
      </visual>
      <gravity>1</gravity>
      <velocity_decay/>
    </link>
    <link name='link2'>
      <pose frame=''>-0.032697 0 0.133514 3.14159 -0.041593 3.14159</pose>
      <inertial>
        <pose frame=''>-0.000302 0.00054 0.047434 0 -0 0</pose>
        <mass>0.0984068</mass>
        <inertia>
          <ixx>3.45434e-05</ixx>
          <ixy>-1.60311e-08</ixy>
          <ixz>-3.83752e-07</ixz>
          <iyy>3.26893e-05</iyy>
          <iyz>2.85119e-08</iyz>
          <izz>1.88503e-05</izz>
        </inertia>
      </inertial>
      <collision name='link2_collision'>
        <pose frame=''>0 0 0.019 0 -0 0</pose>
        <geometry>
          <mesh>
            <scale>0.001 0.001 0.001</scale>
            <uri>model://custom_drone_with_manipulator/meshes/chain_link2.stl</uri>
          </mesh>
        </geometry>
        <surface>
          <contact>
            <ode>
              <kp>1e+06</kp>
              <kd>100</kd>
              <max_vel>1</max_vel>
              <min_depth>0.001</min_depth>
            </ode>
          </contact>
          <friction>
            <ode>
              <mu>30</mu>
              <mu2>30</mu2>
            </ode>
          </friction>
        </surface>
      </collision>
      <visual name='link2_visual'>
        <pose frame=''>0 0 0.019 0 -0 0</pose>
        <geometry>
          <mesh>
            <scale>0.001 0.001 0.001</scale>
            <uri>model://custom_drone_with_manipulator/meshes/chain_link2.stl</uri>
          </mesh>
        </geometry>
        <material>
          <script>
            <name>Gazebo/DarkGrey</name>
            <uri>file://media/materials/scripts/gazebo.material</uri>
          </script>
        </material>
      </visual>
      <gravity>1</gravity>
      <velocity_decay/>
    </link>
    <joint name='joint1' type='revolute'>
      <child>link2</child>
      <parent>custom_drone__fuselage</parent>
      <axis>
        <xyz>-0.041581 0 -0.999135</xyz>
        <limit>
          <lower>-2.82743</lower>
          <upper>2.82743</upper>
          <effort>1</effort>
          <velocity>4.8</velocity>
        </limit>
        <dynamics>
          <spring_reference>0</spring_reference>
          <spring_stiffness>0</spring_stiffness>
        </dynamics>
        <use_parent_model_frame>1</use_parent_model_frame>
      </axis>
    </joint>
    <link name='link3'>
      <pose frame=''>-0.035171 0 0.074065 3.14159 -0.041593 3.14159</pose>
      <inertial>
        <pose frame=''>0.010308 0.000377 0.101702 0 -0 0</pose>
        <mass>0.138509</mass>
        <inertia>
          <ixx>0.000330554</ixx>
          <ixy>-9.7941e-08</ixy>
          <ixz>-3.85057e-05</ixz>
          <iyy>0.000342904</iyy>
          <iyz>-1.57175e-06</iyz>
          <izz>6.03465e-05</izz>
        </inertia>
      </inertial>
      <collision name='link3_collision'>
        <pose frame=''>0 0 0 0 -0 0</pose>
        <geometry>
          <mesh>
            <scale>0.001 0.001 0.001</scale>
            <uri>model://custom_drone_with_manipulator/meshes/chain_link3.stl</uri>
          </mesh>
        </geometry>
        <surface>
          <contact>
            <ode>
              <kp>1e+06</kp>
              <kd>100</kd>
              <max_vel>1</max_vel>
              <min_depth>0.001</min_depth>
            </ode>
          </contact>
          <friction>
            <ode>
              <mu>30</mu>
              <mu2>30</mu2>
            </ode>
          </friction>
        </surface>
      </collision>
      <visual name='link3_visual'>
        <pose frame=''>0 0 0 0 -0 0</pose>
        <geometry>
          <mesh>
            <scale>0.001 0.001 0.001</scale>
            <uri>model://custom_drone_with_manipulator/meshes/chain_link3.stl</uri>
          </mesh>
        </geometry>
        <material>
          <script>
            <name>Gazebo/DarkGrey</name>
            <uri>file://media/materials/scripts/gazebo.material</uri>
          </script>
        </material>
      </visual>
      <gravity>1</gravity>
      <velocity_decay/>
    </link>
    <joint name='joint2' type='revolute'>
      <child>link3</child>
      <parent>link2</parent>
      <axis>
        <xyz>0 1 0</xyz>
        <limit>
          <lower>-1.79071</lower>
          <upper>1.5708</upper>
          <effort>1</effort>
          <velocity>4.8</velocity>
        </limit>
        <dynamics>
          <spring_reference>0</spring_reference>
          <spring_stiffness>0</spring_stiffness>
        </dynamics>
        <use_parent_model_frame>1</use_parent_model_frame>
      </axis>
    </joint>
    <link name='custom_drone__rotor_0'>
      <pose frame=''>0.22981 -0.22981 0.26 0 -0 0</pose>
      <inertial>
        <pose frame=''>0 0 0 0 -0 0</pose>
        <mass>0.019</mass>
        <inertia>
          <ixx>6.34917e-07</ixx>
          <ixy>0</ixy>
          <ixz>0</ixz>
          <iyy>4.31078e-05</iyy>
          <iyz>0</iyz>
          <izz>4.37396e-05</izz>
        </inertia>
      </inertial>
      <collision name='custom_drone__rotor_0_collision_collision'>
        <pose frame=''>0 0 0 0 -0 0</pose>
        <geometry>
          <box>
            <size>0.33 0.02 0.001</size>
          </box>
        </geometry>
      </collision>
      <visual name='custom_drone__rotor_0_visual_visual'>
        <pose frame=''>0 0 0 0 -0 0</pose>
        <geometry>
          <mesh>
            <scale>1 1 1</scale>
            <uri>model://custom_drone_with_manipulator/meshes/dji_13455_prop_ccw.dae</uri>
          </mesh>
        </geometry>
      </visual>
    </link>
    <joint name='custom_drone__rotor_0_joint' type='revolute'>
      <child>custom_drone__rotor_0</child>
      <parent>custom_drone__fuselage</parent>
      <axis>
        <xyz>0 0 1</xyz>
        <limit>
          <lower>-1e+16</lower>
          <upper>1e+16</upper>
          <effort>0</effort>
          <velocity>0</velocity>
        </limit>
        <dynamics>
          <spring_reference>0</spring_reference>
          <spring_stiffness>0</spring_stiffness>
        </dynamics>
        <use_parent_model_frame>1</use_parent_model_frame>
      </axis>
    </joint>
    <link name='custom_drone__rotor_1'>
      <pose frame=''>-0.22981 0.22981 0.26 0 -0 0</pose>
      <inertial>
        <pose frame=''>0 0 0 0 -0 0</pose>
        <mass>0.019</mass>
        <inertia>
          <ixx>6.34917e-07</ixx>
          <ixy>0</ixy>
          <ixz>0</ixz>
          <iyy>4.31078e-05</iyy>
          <iyz>0</iyz>
          <izz>4.37396e-05</izz>
        </inertia>
      </inertial>
      <collision name='custom_drone__rotor_1_collision_collision'>
        <pose frame=''>0 0 0 0 -0 0</pose>
        <geometry>
          <box>
            <size>0.33 0.02 0.001</size>
          </box>
        </geometry>
      </collision>
      <visual name='custom_drone__rotor_1_visual_visual'>
        <pose frame=''>0 0 0 0 -0 0</pose>
        <geometry>
          <mesh>
            <scale>1 1 1</scale>
            <uri>model://custom_drone_with_manipulator/meshes/dji_13455_prop_ccw.dae</uri>
          </mesh>
        </geometry>
      </visual>
    </link>
    <joint name='custom_drone__rotor_1_joint' type='revolute'>
      <child>custom_drone__rotor_1</child>
      <parent>custom_drone__fuselage</parent>
      <axis>
        <xyz>0 0 1</xyz>
        <limit>
          <lower>-1e+16</lower>
          <upper>1e+16</upper>
          <effort>0</effort>
          <velocity>0</velocity>
        </limit>
        <dynamics>
          <spring_reference>0</spring_reference>
          <spring_stiffness>0</spring_stiffness>
        </dynamics>
        <use_parent_model_frame>1</use_parent_model_frame>
      </axis>
    </joint>
    <link name='custom_drone__rotor_2'>
      <pose frame=''>0.22981 0.22981 0.26 0 -0 0</pose>
      <inertial>
        <pose frame=''>0 0 0 0 -0 0</pose>
        <mass>0.019</mass>
        <inertia>
          <ixx>6.34917e-07</ixx>
          <ixy>0</ixy>
          <ixz>0</ixz>
          <iyy>4.31078e-05</iyy>
          <iyz>0</iyz>
          <izz>4.37396e-05</izz>
        </inertia>
      </inertial>
      <collision name='custom_drone__rotor_2_collision_collision'>
        <pose frame=''>0 0 0 0 -0 0</pose>
        <geometry>
          <box>
            <size>0.33 0.02 0.001</size>
          </box>
        </geometry>
      </collision>
      <visual name='custom_drone__rotor_2_visual_visual'>
        <pose frame=''>0 0 0 0 -0 0</pose>
        <geometry>
          <mesh>
            <scale>1 1 1</scale>
            <uri>model://custom_drone_with_manipulator/meshes/dji_13455_prop_cw.dae</uri>
          </mesh>
        </geometry>
      </visual>
    </link>
    <joint name='custom_drone__rotor_2_joint' type='revolute'>
      <child>custom_drone__rotor_2</child>
      <parent>custom_drone__fuselage</parent>
      <axis>
        <xyz>0 0 1</xyz>
        <limit>
          <lower>-1e+16</lower>
          <upper>1e+16</upper>
          <effort>0</effort>
          <velocity>0</velocity>
        </limit>
        <dynamics>
          <spring_reference>0</spring_reference>
          <spring_stiffness>0</spring_stiffness>
        </dynamics>
        <use_parent_model_frame>1</use_parent_model_frame>
      </axis>
    </joint>
    <link name='custom_drone__rotor_3'>
      <pose frame=''>-0.22981 -0.22981 0.26 0 -0 0</pose>
      <inertial>
        <pose frame=''>0 0 0 0 -0 0</pose>
        <mass>0.019</mass>
        <inertia>
          <ixx>6.34917e-07</ixx>
          <ixy>0</ixy>
          <ixz>0</ixz>
          <iyy>4.31078e-05</iyy>
          <iyz>0</iyz>
          <izz>4.37396e-05</izz>
        </inertia>
      </inertial>
      <collision name='custom_drone__rotor_3_collision_collision'>
        <pose frame=''>0 0 0 0 -0 0</pose>
        <geometry>
          <box>
            <size>0.33 0.02 0.001</size>
          </box>
        </geometry>
      </collision>
      <visual name='custom_drone__rotor_3_visual_visual'>
        <pose frame=''>0 0 0 0 -0 0</pose>
        <geometry>
          <mesh>
            <scale>1 1 1</scale>
            <uri>model://custom_drone_with_manipulator/meshes/dji_13455_prop_cw.dae</uri>
          </mesh>
        </geometry>
      </visual>
    </link>
    <joint name='custom_drone__rotor_3_joint' type='revolute'>
      <child>custom_drone__rotor_3</child>
      <parent>custom_drone__fuselage</parent>
      <axis>
        <xyz>0 0 1</xyz>
        <limit>
          <lower>-1e+16</lower>
          <upper>1e+16</upper>
          <effort>0</effort>
          <velocity>0</velocity>
        </limit>
        <dynamics>
          <spring_reference>0</spring_reference>
          <spring_stiffness>0</spring_stiffness>
        </dynamics>
        <use_parent_model_frame>1</use_parent_model_frame>
      </axis>
    </joint>
    <static>0</static>

    <plugin name='gazebo_ros_control' filename='libgazebo_ros_control.so'>
      <robotNamespace>/open_manipulator</robotNamespace>
      <controlPeriod>0.004</controlPeriod>
      <robotSimType>gazebo_ros_control/DefaultRobotHWSim</robotSimType>
      <legacyModeNS>1</legacyModeNS>
    </plugin>
  </model>
</sdf>
